ERROR    asyncio:base_events.py:1785 Exception in callback SyncBase._sync.<locals>.<lambda>(<Task finishe...dy handled!')>) at /opt/hostedtoolcache/Python/3.11.13/x64/lib/python3.11/site-packages/playwright/_impl/_sync_base.py:111
handle: <Handle SyncBase._sync.<locals>.<lambda>(<Task finishe...dy handled!')>) at /opt/hostedtoolcache/Python/3.11.13/x64/lib/python3.11/site-packages/playwright/_impl/_sync_base.py:111>
Traceback (most recent call last):
  File "/opt/hostedtoolcache/Python/3.11.13/x64/lib/python3.11/asyncio/events.py", line 84, in _run
    self._context.run(self._callback, *self._args)
  File "/opt/hostedtoolcache/Python/3.11.13/x64/lib/python3.11/site-packages/playwright/_impl/_sync_base.py", line 111, in <lambda>
    task.add_done_callback(lambda _: g_self.switch())
                                     ^^^^^^^^^^^^^^^
  File "/opt/hostedtoolcache/Python/3.11.13/x64/lib/python3.11/site-packages/playwright/_impl/_connection.py", line 471, in _listener_with_error_handler_attached
    potential_future = listener(params)
                       ^^^^^^^^^^^^^^^^
  File "/opt/hostedtoolcache/Python/3.11.13/x64/lib/python3.11/site-packages/playwright/_impl/_browser_context.py", line 167, in <lambda>
    "dialog", lambda params: self._on_dialog(from_channel(params["dialog"]))
                             ^^^^^^^^^^^^^^^^^^^^^^^^^^^^^^^^^^^^^^^^^^^^^^^
  File "/opt/hostedtoolcache/Python/3.11.13/x64/lib/python3.11/site-packages/playwright/_impl/_browser_context.py", line 708, in _on_dialog
    has_listeners = page.emit(Page.Events.Dialog, dialog) or has_listeners
                    ^^^^^^^^^^^^^^^^^^^^^^^^^^^^^^^^^^^^^
  File "/opt/hostedtoolcache/Python/3.11.13/x64/lib/python3.11/site-packages/pyee/asyncio.py", line 70, in emit
    return super().emit(event, *args, **kwargs)
           ^^^^^^^^^^^^^^^^^^^^^^^^^^^^^^^^^^^^
  File "/opt/hostedtoolcache/Python/3.11.13/x64/lib/python3.11/site-packages/pyee/base.py", line 220, in emit
    handled = self._call_handlers(event, args, kwargs)
              ^^^^^^^^^^^^^^^^^^^^^^^^^^^^^^^^^^^^^^^^
  File "/opt/hostedtoolcache/Python/3.11.13/x64/lib/python3.11/site-packages/pyee/base.py", line 196, in _call_handlers
    self._emit_run(f, args, kwargs)
  File "/opt/hostedtoolcache/Python/3.11.13/x64/lib/python3.11/site-packages/pyee/asyncio.py", line 81, in _emit_run
    self.emit("error", exc)
  File "/opt/hostedtoolcache/Python/3.11.13/x64/lib/python3.11/site-packages/pyee/asyncio.py", line 70, in emit
    return super().emit(event, *args, **kwargs)
           ^^^^^^^^^^^^^^^^^^^^^^^^^^^^^^^^^^^^
  File "/opt/hostedtoolcache/Python/3.11.13/x64/lib/python3.11/site-packages/pyee/base.py", line 223, in emit
    self._emit_handle_potential_error(event, args[0] if args else None)
  File "/opt/hostedtoolcache/Python/3.11.13/x64/lib/python3.11/site-packages/pyee/base.py", line 181, in _emit_handle_potential_error
    raise error
  File "/opt/hostedtoolcache/Python/3.11.13/x64/lib/python3.11/site-packages/pyee/asyncio.py", line 79, in _emit_run
    coro: Any = f(*args, **kwargs)
                ^^^^^^^^^^^^^^^^^^
  File "/opt/hostedtoolcache/Python/3.11.13/x64/lib/python3.11/site-packages/playwright/_impl/_impl_to_api_mapping.py", line 123, in wrapper_func
    return handler(
           ^^^^^^^^
  File "/home/runner/work/PlaywrightDemoblaze/PlaywrightDemoblaze/pages/productpage.py", line 21, in accept_alert
    alert.accept()
  File "/opt/hostedtoolcache/Python/3.11.13/x64/lib/python3.11/site-packages/playwright/sync_api/_generated.py", line 7228, in accept
    self._sync(self._impl_obj.accept(promptText=prompt_text))
  File "/opt/hostedtoolcache/Python/3.11.13/x64/lib/python3.11/site-packages/playwright/_impl/_sync_base.py", line 115, in _sync
    return task.result()
           ^^^^^^^^^^^^^
  File "/opt/hostedtoolcache/Python/3.11.13/x64/lib/python3.11/site-packages/playwright/_impl/_dialog.py", line 51, in accept
    await self._channel.send("accept", None, locals_to_params(locals()))
  File "/opt/hostedtoolcache/Python/3.11.13/x64/lib/python3.11/site-packages/playwright/_impl/_connection.py", line 69, in send
    return await self._connection.wrap_api_call(
           ^^^^^^^^^^^^^^^^^^^^^^^^^^^^^^^^^^^^^
  File "/opt/hostedtoolcache/Python/3.11.13/x64/lib/python3.11/site-packages/playwright/_impl/_connection.py", line 558, in wrap_api_call
    raise rewrite_error(error, f"{parsed_st['apiName']}: {error}") from None
playwright._impl._errors.Error: Dialog.accept: Cannot accept dialog which is already handled!